[2024-08-23T03:18:42.403+0000] {local_task_job_runner.py:120} INFO - ::group::Pre task execution logs
[2024-08-23T03:18:42.432+0000] {taskinstance.py:2076} INFO - Dependencies all met for dep_context=non-requeueable deps ti=<TaskInstance: update_stock_data_hour_into_s3_123.update_parquet_file_1 scheduled__2024-08-23T02:01:00+00:00 [queued]>
[2024-08-23T03:18:42.442+0000] {taskinstance.py:2076} INFO - Dependencies all met for dep_context=requeueable deps ti=<TaskInstance: update_stock_data_hour_into_s3_123.update_parquet_file_1 scheduled__2024-08-23T02:01:00+00:00 [queued]>
[2024-08-23T03:18:42.443+0000] {taskinstance.py:2306} INFO - Starting attempt 1 of 1
[2024-08-23T03:18:42.455+0000] {taskinstance.py:2330} INFO - Executing <Task(_PythonDecoratedOperator): update_parquet_file_1> on 2024-08-23 02:01:00+00:00
[2024-08-23T03:18:42.465+0000] {logging_mixin.py:188} WARNING - /home/***/.local/lib/python3.12/site-packages/***/task/task_runner/standard_task_runner.py:62 DeprecationWarning: This process (pid=528) is multi-threaded, use of fork() may lead to deadlocks in the child.
[2024-08-23T03:18:42.466+0000] {standard_task_runner.py:64} INFO - Started process 539 to run task
[2024-08-23T03:18:42.465+0000] {standard_task_runner.py:90} INFO - Running: ['***', 'tasks', 'run', 'update_stock_data_hour_into_s3_123', 'update_parquet_file_1', 'scheduled__2024-08-23T02:01:00+00:00', '--job-id', '71', '--raw', '--subdir', 'DAGS_FOLDER/load_data_into_s3_hour.py', '--cfg-path', '/tmp/tmpg8us4zkx']
[2024-08-23T03:18:42.468+0000] {standard_task_runner.py:91} INFO - Job 71: Subtask update_parquet_file_1
[2024-08-23T03:18:42.482+0000] {logging_mixin.py:188} WARNING - /home/***/.local/lib/python3.12/site-packages/***/settings.py:195 DeprecationWarning: The sql_alchemy_conn option in [core] has been moved to the sql_alchemy_conn option in [database] - the old setting has been used, but please update your config.
[2024-08-23T03:18:42.526+0000] {task_command.py:426} INFO - Running <TaskInstance: update_stock_data_hour_into_s3_123.update_parquet_file_1 scheduled__2024-08-23T02:01:00+00:00 [running]> on host fa4e08fee2f6
[2024-08-23T03:18:42.787+0000] {taskinstance.py:2648} INFO - Exporting env vars: AIRFLOW_CTX_DAG_OWNER='***' AIRFLOW_CTX_DAG_ID='update_stock_data_hour_into_s3_123' AIRFLOW_CTX_TASK_ID='update_parquet_file_1' AIRFLOW_CTX_EXECUTION_DATE='2024-08-23T02:01:00+00:00' AIRFLOW_CTX_TRY_NUMBER='1' AIRFLOW_CTX_DAG_RUN_ID='scheduled__2024-08-23T02:01:00+00:00'
[2024-08-23T03:18:42.790+0000] {taskinstance.py:430} INFO - ::endgroup::
[2024-08-23T03:18:50.801+0000] {connectionpool.py:872} WARNING - Retrying (Retry(total=4, connect=None, read=None, redirect=None, status=None)) after connection broken by 'NameResolutionError("<urllib3.connection.HTTPConnection object at 0x7fbb70e0cbf0>: Failed to resolve 'minio' ([Errno -3] Temporary failure in name resolution)")': /stock-data-hour?location=
[2024-08-23T03:18:59.217+0000] {connectionpool.py:872} WARNING - Retrying (Retry(total=3, connect=None, read=None, redirect=None, status=None)) after connection broken by 'NameResolutionError("<urllib3.connection.HTTPConnection object at 0x7fbb70e0d220>: Failed to resolve 'minio' ([Errno -3] Temporary failure in name resolution)")': /stock-data-hour?location=
[2024-08-23T03:19:08.021+0000] {connectionpool.py:872} WARNING - Retrying (Retry(total=2, connect=None, read=None, redirect=None, status=None)) after connection broken by 'NameResolutionError("<urllib3.connection.HTTPConnection object at 0x7fbb70e0d610>: Failed to resolve 'minio' ([Errno -3] Temporary failure in name resolution)")': /stock-data-hour?location=
[2024-08-23T03:19:17.627+0000] {connectionpool.py:872} WARNING - Retrying (Retry(total=1, connect=None, read=None, redirect=None, status=None)) after connection broken by 'NameResolutionError("<urllib3.connection.HTTPConnection object at 0x7fbb70e0d670>: Failed to resolve 'minio' ([Errno -3] Temporary failure in name resolution)")': /stock-data-hour?location=
[2024-08-23T03:19:28.836+0000] {connectionpool.py:872} WARNING - Retrying (Retry(total=0, connect=None, read=None, redirect=None, status=None)) after connection broken by 'NameResolutionError("<urllib3.connection.HTTPConnection object at 0x7fbb70e0de20>: Failed to resolve 'minio' ([Errno -3] Temporary failure in name resolution)")': /stock-data-hour?location=
[2024-08-23T03:19:36.851+0000] {taskinstance.py:441} INFO - ::group::Post task execution logs
[2024-08-23T03:19:36.865+0000] {taskinstance.py:2905} ERROR - Task failed with exception
Traceback (most recent call last):
  File "/home/airflow/.local/lib/python3.12/site-packages/urllib3/connection.py", line 203, in _new_conn
    sock = connection.create_connection(
           ^^^^^^^^^^^^^^^^^^^^^^^^^^^^^
  File "/home/airflow/.local/lib/python3.12/site-packages/urllib3/util/connection.py", line 60, in create_connection
    for res in socket.getaddrinfo(host, port, family, socket.SOCK_STREAM):
               ^^^^^^^^^^^^^^^^^^^^^^^^^^^^^^^^^^^^^^^^^^^^^^^^^^^^^^^^^^
  File "/usr/local/lib/python3.12/socket.py", line 964, in getaddrinfo
    for res in _socket.getaddrinfo(host, port, family, type, proto, flags):
               ^^^^^^^^^^^^^^^^^^^^^^^^^^^^^^^^^^^^^^^^^^^^^^^^^^^^^^^^^^^
socket.gaierror: [Errno -3] Temporary failure in name resolution

The above exception was the direct cause of the following exception:

Traceback (most recent call last):
  File "/home/airflow/.local/lib/python3.12/site-packages/urllib3/connectionpool.py", line 791, in urlopen
    response = self._make_request(
               ^^^^^^^^^^^^^^^^^^^
  File "/home/airflow/.local/lib/python3.12/site-packages/urllib3/connectionpool.py", line 497, in _make_request
    conn.request(
  File "/home/airflow/.local/lib/python3.12/site-packages/urllib3/connection.py", line 395, in request
    self.endheaders()
  File "/usr/local/lib/python3.12/http/client.py", line 1331, in endheaders
    self._send_output(message_body, encode_chunked=encode_chunked)
  File "/usr/local/lib/python3.12/http/client.py", line 1091, in _send_output
    self.send(msg)
  File "/usr/local/lib/python3.12/http/client.py", line 1035, in send
    self.connect()
  File "/home/airflow/.local/lib/python3.12/site-packages/urllib3/connection.py", line 243, in connect
    self.sock = self._new_conn()
                ^^^^^^^^^^^^^^^^
  File "/home/airflow/.local/lib/python3.12/site-packages/urllib3/connection.py", line 210, in _new_conn
    raise NameResolutionError(self.host, self, e) from e
urllib3.exceptions.NameResolutionError: <urllib3.connection.HTTPConnection object at 0x7fbb70e0e180>: Failed to resolve 'minio' ([Errno -3] Temporary failure in name resolution)

The above exception was the direct cause of the following exception:

Traceback (most recent call last):
  File "/home/airflow/.local/lib/python3.12/site-packages/airflow/models/taskinstance.py", line 465, in _execute_task
    result = _execute_callable(context=context, **execute_callable_kwargs)
             ^^^^^^^^^^^^^^^^^^^^^^^^^^^^^^^^^^^^^^^^^^^^^^^^^^^^^^^^^^^^^
  File "/home/airflow/.local/lib/python3.12/site-packages/airflow/models/taskinstance.py", line 432, in _execute_callable
    return execute_callable(context=context, **execute_callable_kwargs)
           ^^^^^^^^^^^^^^^^^^^^^^^^^^^^^^^^^^^^^^^^^^^^^^^^^^^^^^^^^^^^
  File "/home/airflow/.local/lib/python3.12/site-packages/airflow/models/baseoperator.py", line 401, in wrapper
    return func(self, *args, **kwargs)
           ^^^^^^^^^^^^^^^^^^^^^^^^^^^
  File "/home/airflow/.local/lib/python3.12/site-packages/airflow/decorators/base.py", line 265, in execute
    return_value = super().execute(context)
                   ^^^^^^^^^^^^^^^^^^^^^^^^
  File "/home/airflow/.local/lib/python3.12/site-packages/airflow/models/baseoperator.py", line 401, in wrapper
    return func(self, *args, **kwargs)
           ^^^^^^^^^^^^^^^^^^^^^^^^^^^
  File "/home/airflow/.local/lib/python3.12/site-packages/airflow/operators/python.py", line 235, in execute
    return_value = self.execute_callable()
                   ^^^^^^^^^^^^^^^^^^^^^^^
  File "/home/airflow/.local/lib/python3.12/site-packages/airflow/operators/python.py", line 252, in execute_callable
    return self.python_callable(*self.op_args, **self.op_kwargs)
           ^^^^^^^^^^^^^^^^^^^^^^^^^^^^^^^^^^^^^^^^^^^^^^^^^^^^^
  File "/opt/airflow/dags/load_data_into_s3_hour.py", line 88, in update_parquet_file_1
    if minio_client.bucket_exists(minio_bucket_name):
       ^^^^^^^^^^^^^^^^^^^^^^^^^^^^^^^^^^^^^^^^^^^^^
  File "/home/airflow/.local/lib/python3.12/site-packages/minio/api.py", line 696, in bucket_exists
    self._execute("HEAD", bucket_name)
  File "/home/airflow/.local/lib/python3.12/site-packages/minio/api.py", line 437, in _execute
    region = self._get_region(bucket_name)
             ^^^^^^^^^^^^^^^^^^^^^^^^^^^^^
  File "/home/airflow/.local/lib/python3.12/site-packages/minio/api.py", line 494, in _get_region
    response = self._url_open(
               ^^^^^^^^^^^^^^^
  File "/home/airflow/.local/lib/python3.12/site-packages/minio/api.py", line 302, in _url_open
    response = self._http.urlopen(
               ^^^^^^^^^^^^^^^^^^^
  File "/home/airflow/.local/lib/python3.12/site-packages/urllib3/poolmanager.py", line 443, in urlopen
    response = conn.urlopen(method, u.request_uri, **kw)
               ^^^^^^^^^^^^^^^^^^^^^^^^^^^^^^^^^^^^^^^^^
  File "/home/airflow/.local/lib/python3.12/site-packages/urllib3/connectionpool.py", line 875, in urlopen
    return self.urlopen(
           ^^^^^^^^^^^^^
  File "/home/airflow/.local/lib/python3.12/site-packages/urllib3/connectionpool.py", line 875, in urlopen
    return self.urlopen(
           ^^^^^^^^^^^^^
  File "/home/airflow/.local/lib/python3.12/site-packages/urllib3/connectionpool.py", line 875, in urlopen
    return self.urlopen(
           ^^^^^^^^^^^^^
  [Previous line repeated 2 more times]
  File "/home/airflow/.local/lib/python3.12/site-packages/urllib3/connectionpool.py", line 845, in urlopen
    retries = retries.increment(
              ^^^^^^^^^^^^^^^^^^
  File "/home/airflow/.local/lib/python3.12/site-packages/urllib3/util/retry.py", line 515, in increment
    raise MaxRetryError(_pool, url, reason) from reason  # type: ignore[arg-type]
    ^^^^^^^^^^^^^^^^^^^^^^^^^^^^^^^^^^^^^^^^^^^^^^^^^^^
urllib3.exceptions.MaxRetryError: HTTPConnectionPool(host='minio', port=9000): Max retries exceeded with url: /stock-data-hour?location= (Caused by NameResolutionError("<urllib3.connection.HTTPConnection object at 0x7fbb70e0e180>: Failed to resolve 'minio' ([Errno -3] Temporary failure in name resolution)"))
[2024-08-23T03:19:37.035+0000] {taskinstance.py:1206} INFO - Marking task as FAILED. dag_id=update_stock_data_hour_into_s3_123, task_id=update_parquet_file_1, run_id=scheduled__2024-08-23T02:01:00+00:00, execution_date=20240823T020100, start_date=20240823T031842, end_date=20240823T031937
[2024-08-23T03:19:37.097+0000] {standard_task_runner.py:110} ERROR - Failed to execute job 71 for task update_parquet_file_1 (HTTPConnectionPool(host='minio', port=9000): Max retries exceeded with url: /stock-data-hour?location= (Caused by NameResolutionError("<urllib3.connection.HTTPConnection object at 0x7fbb70e0e180>: Failed to resolve 'minio' ([Errno -3] Temporary failure in name resolution)")); 539)
[2024-08-23T03:19:37.145+0000] {local_task_job_runner.py:243} INFO - Task exited with return code 1
[2024-08-23T03:19:37.208+0000] {local_task_job_runner.py:222} INFO - ::endgroup::
